Workbook

Sheet Inputs
A1: Saluz data and core inputs
A3: Input incremental triangle
B4: Dev 1 | C4: Dev 2 | D4: Dev 3 | E4: Dev 4 | F4: Dev 5 | G4: Dev 6 | H4: Dev 7 | I4: Dev 8 | J4: Dev 9 | K4: Dev 10 | L4: Premium | M4: Latest paid | N4: Maturity age
A5: Origin 1 | B5: 5946975.4 | C5: 3721236.6 | D5: 895717.29 | E5: 207760.33 | F5: 206703.99 | G5: 62124.15 | H5: 65813.42 | I5: 14849.66 | J5: 11129.53 | K5: 15813.42 | L5: 15473558 | M5: =SUM(B5:K5) -> 11148124 | N5: 10
A6: Origin 2 | B6: 6346756.1 | C6: 3246405.6 | D6: 723221.75 | E6: 151796.78 | F6: 67824.093 | G6: 36603.479 | H6: 52752.072 | I6: 11186.393 | J6: 11645.529 | L6: 14882436 | M6: =SUM(B6:J6) -> 10648192 | N6: 9
A7: Origin 3 | B7: 6269090.2 | C7: 2976223.1 | D7: 847052.7 | E7: 262768.32 | F7: 152703.1 | G7: 65444.185 | H7: 53545.242 | I7: 8924.2071 | L7: 14456039 | M7: =SUM(B7:I7) -> 10635751 | N7: 8
A8: Origin 4 | B8: 5863014.8 | C8: 2683224.3 | D8: 722531.72 | E8: 190652.73 | F8: 132975.59 | G8: 88340.429 | H8: 43328.63 | L8: 14054917 | M8: =SUM(B8:H8) -> 9724068.2 | N8: 7
A9: Origin 5 | B9: 5778885.4 | C9: 2745228.9 | D9: 653894.36 | E9: 273395.49 | F9: 230287.56 | G9: 105224.38 | L9: 14525373 | M9: =SUM(B9:G9) -> 9786916.1 | N9: 6
A10: Origin 6 | B10: 6184793.4 | C10: 2828338.5 | D10: 572764.78 | E10: 244899.43 | F10: 104956.9 | L10: 15025923 | M10: =SUM(B10:F10) -> 9935753 | N10: 5
A11: Origin 7 | B11: 5600184.4 | C11: 2893206.9 | D11: 563113.91 | E11: 225517.01 | L11: 14832965 | M11: =SUM(B11:E11) -> 9282022.2 | N11: 4
A12: Origin 8 | B12: 5288065.6 | C12: 2440103.2 | D12: 528042.56 | L12: 14550359 | M12: =SUM(B12:D12) -> 8256211.4 | N12: 3
A13: Origin 9 | B13: 5290792.9 | C13: 2357936 | L13: 14461781 | M13: =SUM(B13:C13) -> 7648728.9 | N13: 2
A14: Origin 10 | B14: 5675568.1 | L14: 15210363 | M14: =SUM(B14) -> 5675568.1 | N14: 1
A18: Cumulative triangle
B19: Age 1 | C19: Age 2 | D19: Age 3 | E19: Age 4 | F19: Age 5 | G19: Age 6 | H19: Age 7 | I19: Age 8 | J19: Age 9 | K19: Age 10
A20: Origin 1 | B20: =IF(B5="","",B5) -> 5946975.4 | C20: =IF(C5="","",B20+C5) -> 9668212 | D20: =IF(D5="","",C20+D5) -> 10563929 | E20: =IF(E5="","",D20+E5) -> 10771690 | F20: =IF(F5="","",E20+F5) -> 10978394 | G20: =IF(G5="","",F20+G5) -> 11040518 | H20: =IF(H5="","",G20+H5) -> 11106331 | I20: =IF(I5="","",H20+I5) -> 11121181 | J20: =IF(J5="","",I20+J5) -> 11132310 | K20: =IF(K5="","",J20+K5) -> 11148124
A21: Origin 2 | B21: =IF(B6="","",B6) -> 6346756.1 | C21: =IF(C6="","",B21+C6) -> 9593161.7 | D21: =IF(D6="","",C21+D6) -> 10316383 | E21: =IF(E6="","",D21+E6) -> 10468180 | F21: =IF(F6="","",E21+F6) -> 10536004 | G21: =IF(G6="","",F21+G6) -> 10572608 | H21: =IF(H6="","",G21+H6) -> 10625360 | I21: =IF(I6="","",H21+I6) -> 10636546 | J21: =IF(J6="","",I21+J6) -> 10648192
A22: Origin 3 | B22: =IF(B7="","",B7) -> 6269090.2 | C22: =IF(C7="","",B22+C7) -> 9245313.3 | D22: =IF(D7="","",C22+D7) -> 10092366 | E22: =IF(E7="","",D22+E7) -> 10355134 | F22: =IF(F7="","",E22+F7) -> 10507837 | G22: =IF(G7="","",F22+G7) -> 10573282 | H22: =IF(H7="","",G22+H7) -> 10626827 | I22: =IF(I7="","",H22+I7) -> 10635751
A23: Origin 4 | B23: =IF(B8="","",B8) -> 5863014.8 | C23: =IF(C8="","",B23+C8) -> 8546239.1 | D23: =IF(D8="","",C23+D8) -> 9268770.8 | E23: =IF(E8="","",D23+E8) -> 9459423.6 | F23: =IF(F8="","",E23+F8) -> 9592399.2 | G23: =IF(G8="","",F23+G8) -> 9680739.6 | H23: =IF(H8="","",G23+H8) -> 9724068.2
A24: Origin 5 | B24: =IF(B9="","",B9) -> 5778885.4 | C24: =IF(C9="","",B24+C9) -> 8524114.3 | D24: =IF(D9="","",C24+D9) -> 9178008.6 | E24: =IF(E9="","",D24+E9) -> 9451404.1 | F24: =IF(F9="","",E24+F9) -> 9681691.7 | G24: =IF(G9="","",F24+G9) -> 9786916.1
A25: Origin 6 | B25: =IF(B10="","",B10) -> 6184793.4 | C25: =IF(C10="","",B25+C10) -> 9013131.9 | D25: =IF(D10="","",C25+D10) -> 9585896.7 | E25: =IF(E10="","",D25+E10) -> 9830796.1 | F25: =IF(F10="","",E25+F10) -> 9935753
A26: Origin 7 | B26: =IF(B11="","",B11) -> 5600184.4 | C26: =IF(C11="","",B26+C11) -> 8493391.3 | D26: =IF(D11="","",C26+D11) -> 9056505.2 | E26: =IF(E11="","",D26+E11) -> 9282022.2
A27: Origin 8 | B27: =IF(B12="","",B12) -> 5288065.6 | C27: =IF(C12="","",B27+C12) -> 7728168.8 | D27: =IF(D12="","",C27+D12) -> 8256211.4
A28: Origin 9 | B28: =IF(B13="","",B13) -> 5290792.9 | C28: =IF(C13="","",B28+C13) -> 7648728.9
A29: Origin 10 | B29: =IF(B14="","",B14) -> 5675568.1
C30: =SUM(C20:C28)/SUM(B20:B28) -> 1.4925359 | D30: =SUM(D20:D27)/SUM(C20:C27) -> 1.0777603 | E30: =SUM(E20:E26)/SUM(D20:D26) -> 1.0228732 | F30: =SUM(F20:F25)/SUM(E20:E25) -> 1.0148409 | G30: =SUM(G20:G24)/SUM(F20:F24) -> 1.0069739 | H30: =SUM(H20:H23)/SUM(G20:G23) -> 1.0051458 | I30: =SUM(I20:I22)/SUM(H20:H22) -> 1.0010804 | J30: =SUM(J20:J21)/SUM(I20:I21) -> 1.0010468 | K30: =SUM(K20)/SUM(J20) -> 1.0014205
A32: Observed column totals and exposure sums
A33: Dev age | B33: 1 | C33: 2 | D33: 3 | E33: 4 | F33: 5 | G33: 6 | H33: 7 | I33: 8 | J33: 9 | K33: 10
A34: C_j | B34: =SUM(B5:B14) -> 58244126 | C34: =SUM(C5:C14) -> 25891903 | D34: =SUM(D5:D14) -> 5506339.1 | E34: =SUM(E5:E14) -> 1556790.1 | F34: =SUM(F5:F14) -> 895451.23 | G34: =SUM(G5:G14) -> 357736.62 | H34: =SUM(H5:H14) -> 215439.36 | I34: =SUM(I5:I14) -> 34960.26 | ... K34: =SUM(K5:K14) -> 15813.42
A35: E_{n-j+1} | B35: =SUM($L$5:$L$14) -> 1.4747372e+08 | C35: =SUM($L$5:$L$13) -> 1.3226335e+08 | D35: =SUM($L$5:$L$12) -> 1.1780157e+08 | E35: =SUM($L$5:$L$11) -> 1.0325121e+08 | F35: =SUM($L$5:$L$10) -> 88418247 | G35: =SUM($L$5:$L$9) -> 73392324 | H35: =SUM($L$5:$L$8) -> 58866951 | I35: =SUM($L$5:$L$7) -> 44812034 | J35: =SUM($L$5:$L$6) -> 30355994 | K35: =SUM($L$5) -> 15473558
A37: Scale parameter estimation and scaled claims
A39: Observed cells N | B39: =COUNT(B5:K14) -> 55 | D39: CC ODP phi (Saluz default) | E39: =SUM(B116:K125)/B41 -> 21610.842
A40: CC ODP parameters (J+1) | B40: =COUNT(B34:K34) -> 10 | D40: CL ODP phi | E40: =SUM(B89:K98)/(B39-(2*COUNT(L5:L14)-1)) -> 14714.098
A41: CC degrees of freedom | B41: =B39-B40 -> 45 | D41: Note | E41: Leave B43 blank to use CC phi by default.
A42: Selected phi | B42: =IF(B43="",E39,B43) -> 21610.842
A43: Optional manual phi override
A44: Chain Ladder fitted incremental means (for CL phi) | B44: Dev 1 | C44: Dev 2 | D44: Dev 3 | E44: Dev 4 | F44: Dev 5 | G44: Dev 6 | H44: Dev 7 | I44: Dev 8 | J44: Dev 9 | K44: Dev 10
A45: Origin 1 | B45: =Methods!$F$19*Methods!$D$5 -> 6572763.3 | C45: =Methods!$F$19*(Methods!$D$6-Methods!$D$5) -> 3237322 | D45: =Methods!$F$19*(Methods!$D$7-Methods!$D$6) -> 762834.83 | E45: =Methods!$F$19*(Methods!$D$8-Methods!$D$7) -> 241836.13 | F45: =Methods!$F$19*(Methods!$D$9-Methods!$D$8) -> 160500.96 | G45: =Methods!$F$19*(Methods!$D$10-Methods!$D$9) -> 76540.597 | H45: =Methods!$F$19*(Methods!$D$11-Methods!$D$10) -> 56870.183 | I45: =Methods!$F$19*(Methods!$D$12-Methods!$D$11) -> 12001.845 | J45: =Methods!$F$19*(Methods!$D$13-Methods!$D$12) -> 11640.642 | K45: =Methods!$F$19*(Methods!$D$14-Methods!$D$13) -> 15813.42
A46: Origin 2 | B46: =Methods!$F$20*Methods!$D$5 -> 6286928.9 | C46: =Methods!$F$20*(Methods!$D$6-Methods!$D$5) -> 3096538.3 | D46: =Methods!$F$20*(Methods!$D$7-Methods!$D$6) -> 729660.89 | E46: =Methods!$F$20*(Methods!$D$8-Methods!$D$7) -> 231319.23 | F46: =Methods!$F$20*(Methods!$D$9-Methods!$D$8) -> 153521.14 | G46: =Methods!$F$20*(Methods!$D$10-Methods!$D$9) -> 73212.022 | H46: =Methods!$F$20*(Methods!$D$11-Methods!$D$10) -> 54397.029 | I46: =Methods!$F$20*(Methods!$D$12-Methods!$D$11) -> 11479.912 | J46: =Methods!$F$20*(Methods!$D$13-Methods!$D$12) -> 11134.417
A47: Origin 3 | B47: =Methods!$F$21*Methods!$D$5 -> 6286156.8 | C47: =Methods!$F$21*(Methods!$D$6-Methods!$D$5) -> 3096158 | D47: =Methods!$F$21*(Methods!$D$7-Methods!$D$6) -> 729571.28 | E47: =Methods!$F$21*(Methods!$D$8-Methods!$D$7) -> 231290.83 | F47: =Methods!$F$21*(Methods!$D$9-Methods!$D$8) -> 153502.29 | G47: =Methods!$F$21*(Methods!$D$10-Methods!$D$9) -> 73203.031 | H47: =Methods!$F$21*(Methods!$D$11-Methods!$D$10) -> 54390.348 | I47: =Methods!$F$21*(Methods!$D$12-Methods!$D$11) -> 11478.502
...

Sheet Reserve SD
A1: Reserve uncertainty by method
A2: Reserve Standard Deviation and Coefficient of Variation
B3: Chain Ladder | D3: Hierarchical | F3: Cape Cod
A4: Origin | B4: SD | C4: CoV | D4: SD | E4: CoV | F4: SD | G4: CoV
A5: Origin 1 | B5: 0 | D5: 0 | F5: 0
A6: Origin 2 | B6: =SQRT('Chain Ladder'!AC10) -> 25331.768 | C6: =B6/Methods!H20 -> 1.6747467 | D6: =SQRT(Hierarchical!AC10) -> 25356.497 | E6: =D6/Hierarchical!K10 -> 1.6726678 | F6: =SQRT('Cape Cod'!AC10) -> 25393.221 | G6: =F6/'Cape Cod'!K10 -> 1.6695835
A7: Origin 3 | B7: =SQRT('Chain Ladder'!AC11) -> 31647.079 | C7: =B7/Methods!H21 -> 1.2052851 | D7: =SQRT(Hierarchical!AC11) -> 31403.24 | E7: =D7/Hierarchical!K11 -> 1.2077975 | F7: =SQRT('Cape Cod'!AC11) -> 31041.121 | G7: =F7/'Cape Cod'!K11 -> 1.2116246
A8: Origin 4 | B8: =SQRT('Chain Ladder'!AC12) -> 34357.499 | C8: =B8/Methods!H22 -> 0.99477188 | D8: =SQRT(Hierarchical!AC12) -> 34685.96 | E8: =D8/Hierarchical!K12 -> 0.98890937 | F8: =SQRT('Cape Cod'!AC12) -> 35171.592 | G8: =F8/'Cape Cod'!K12 -> 0.98043291
A9: Origin 5 | B9: =SQRT('Chain Ladder'!AC13) -> 50588.917 | C9: =B9/Methods!H23 -> 0.59305984 | D9: =SQRT(Hierarchical!AC13) -> 51251.236 | E9: =D9/Hierarchical!K13 -> 0.5871107 | F9: =SQRT('Cape Cod'!AC13) -> 52217.951 | G9: =F9/'Cape Cod'!K13 -> 0.57869611
A10: Origin 6 | B10: =SQRT('Chain Ladder'!AC14) -> 66816.425 | C10: =B10/Methods!H24 -> 0.42695868 | D10: =SQRT(Hierarchical!AC14) -> 67695.77 | E10: =D10/Hierarchical!K14 -> 0.42152447 | F10: =SQRT('Cape Cod'!AC14) -> 68958.082 | G10: =F10/'Cape Cod'!K14 -> 0.4139532
A11: Origin 7 | B11: =SQRT('Chain Ladder'!AC15) -> 88204.031 | C11: =B11/Methods!H25 -> 0.30827557 | D11: =SQRT(Hierarchical!AC15) -> 89813.897 | E11: =D11/Hierarchical!K15 -> 0.30151209 | F11: =SQRT('Cape Cod'!AC15) -> 92035.323 | G11: =F11/'Cape Cod'!K15 -> 0.29248658
A12: Origin 8 | B12: =SQRT('Chain Ladder'!AC16) -> 109265.13 | C12: =B12/Methods!H26 -> 0.24326185 | D12: =SQRT(Hierarchical!AC16) -> 112632.86 | E12: =D12/Hierarchical!K16 -> 0.2335584 | F12: =SQRT('Cape Cod'!AC16) -> 116992.04 | G12: =F12/'Cape Cod'!K16 -> 0.22155243
A13: Origin 9 | B13: =SQRT('Chain Ladder'!AC17) -> 170259.27 | C13: =B13/Methods!H27 -> 0.16320206 | D13: =SQRT(Hierarchical!AC17) -> 171871.45 | E13: =D13/Hierarchical!K17 -> 0.15447777 | F13: =SQRT('Cape Cod'!AC17) -> 173181.79 | G13: =F13/'Cape Cod'!K17 -> 0.14421951
A14: Origin 10 | B14: =SQRT('Chain Ladder'!AC18) -> 401963.29 | C14: =B14/Methods!H28 -> 0.10174187 | D14: =SQRT(Hierarchical!AC18) -> 361871.14 | E14: =D14/Hierarchical!K18 -> 0.088141589 | F14: =SQRT('Cape Cod'!AC18) -> 321733.7 | G14: =F14/'Cape Cod'!K18 -> 0.075870522
A15: Total | B15: =SQRT('Chain Ladder'!AC20) -> 521137.4 | C15: =B15/SUM(Methods!H19:H28) -> 0.086180283 | D15: =SQRT(Hierarchical!AC20) -> 496973.62 | E15: =D15/Hierarchical!K20 -> 0.078605036 | F15: =SQRT('Cape Cod'!AC20) -> 476815.39 | G15: =F15/'Cape Cod'!K20 -> 0.072052347

Sheet Reserves
A1: Reserves and Ultimate Loss Ratios
B3: Chain Ladder | D3: Hierarchical | F3: Cape Cod
A4: Origin | B4: Reserve | C4: LR | D4: Reserve | E4: LR | F4: Reserve | G4: LR
A5: Origin 1 | B5: 0 | C5: ='Chain Ladder'!L9/'Chain Ladder'!B9 -> 0.72046284 | D5: 0 | E5: =Hierarchical!M9 -> 0.72046284 | F5: 0 | G5: ='Cape Cod'!M9 -> 0.72046284
A6: Origin 2 | B6: ='Chain Ladder'!K10 -> 15125.731 | C6: ='Chain Ladder'!L10/'Chain Ladder'!B10 -> 0.7165035 | D6: =Hierarchical!K10 -> 15159.315 | E6: =Hierarchical!M10 -> 0.71650576 | F6: ='Cape Cod'!K10 -> 15209.314 | G6: ='Cape Cod'!M10 -> 0.71650912
A7: Origin 3 | B7: ='Chain Ladder'!K11 -> 26256.923 | C7: ='Chain Ladder'!L11/'Chain Ladder'!B11 -> 0.73754696 | D7: =Hierarchical!K11 -> 26000.418 | E7: =Hierarchical!M11 -> 0.73752922 | F7: ='Cape Cod'!K11 -> 25619.422 | G7: ='Cape Cod'!M11 -> 0.73750286
A8: Origin 4 | B8: ='Chain Ladder'!K12 -> 34538.068 | C8: ='Chain Ladder'!L12/'Chain Ladder'!B12 -> 0.69431972 | D8: =Hierarchical!K12 -> 35074.964 | E8: =Hierarchical!M12 -> 0.69435792 | F8: ='Cape Cod'!K12 -> 35873.533 | G8: ='Cape Cod'!M12 -> 0.69441474
A9: Origin 5 | B9: ='Chain Ladder'!K13 -> 85301.539 | C9: ='Chain Ladder'!L13/'Chain Ladder'!B13 -> 0.67965331 | D9: =Hierarchical!K13 -> 87293.991 | E9: =Hierarchical!M13 -> 0.67979048 | F9: ='Cape Cod'!K13 -> 90233.804 | G9: ='Cape Cod'!M13 -> 0.67999287
A10: Origin 6 | B10: ='Chain Ladder'!K14 -> 156493.89 | C10: ='Chain Ladder'!L14/'Chain Ladder'!B14 -> 0.67165568 | D10: =Hierarchical!K14 -> 160597.49 | E10: =Hierarchical!M14 -> 0.67192878 | F10: ='Cape Cod'!K14 -> 166584.25 | G10: ='Cape Cod'!M14 -> 0.67232721
A11: Origin 7 | B11: ='Chain Ladder'!K15 -> 286120.73 | C11: ='Chain Ladder'!L15/'Chain Ladder'!B15 -> 0.64505935 | D11: =Hierarchical!K15 -> 297878.26 | E11: =Hierarchical!M15 -> 0.64585201 | F11: ='Cape Cod'!K15 -> 314665.11 | G11: ='Cape Cod'!M15 -> 0.64698374
A12: Origin 8 | B12: ='Chain Ladder'!K16 -> 449166.73 | C12: ='Chain Ladder'!L16/'Chain Ladder'!B16 -> 0.59829301 | D12: =Hierarchical!K16 -> 482247.11 | E12: =Hierarchical!M16 -> 0.60056652 | F12: ='Cape Cod'!K16 -> 528055.78 | G12: ='Cape Cod'!M16 -> 0.6037148
A13: Origin 9 | B13: ='Chain Ladder'!K17 -> 1043242.2 | C13: ='Chain Ladder'!L17/'Chain Ladder'!B17 -> 0.60103046 | D13: =Hierarchical!K17 -> 1112596.7 | E13: =Hierarchical!M17 -> 0.60582617 | F13: ='Cape Cod'!K17 -> 1200820.8 | G13: ='Cape Cod'!M17 -> 0.61192668
A14: Origin 10 | B14: ='Chain Ladder'!K18 -> 3950814.8 | C14: ='Chain Ladder'!L18/'Chain Ladder'!B18 -> 0.63288319 | D14: =Hierarchical!K18 -> 4105566.3 | E14: =Hierarchical!M18 -> 0.64305727 | F14: ='Cape Cod'!K18 -> 4240562.6 | G14: ='Cape Cod'!M18 -> 0.65193256
A15: Total | B15: ='Chain Ladder'!K20 -> 6047060.6 | C15: ='Chain Ladder'!L20/'Chain Ladder'!B20 -> 0.6698712 | D15: =Hierarchical!K20 -> 6322414.6 | E15: =Hierarchical!M20 -> 0.67173834 | F15: ='Cape Cod'!K20 -> 6617624.7 | G15: ='Cape Cod'!M20 -> 0.67374012

Sheet Implied Credibility Weight
A1: Implied Credibility Weight
A3: Origin | B3: Effective Credibility
A4: Origin 1
A5: Origin 2 | B5: =(Reserves!D6-Reserves!F6)/(Reserves!B6-Reserves!F6) -> 0.59820058
A6: Origin 3 | B6: =(Reserves!D7-Reserves!F7)/(Reserves!B7-Reserves!F7) -> 0.59764089
A7: Origin 4 | B7: =(Reserves!D8-Reserves!F8)/(Reserves!B8-Reserves!F8) -> 0.59797086
A8: Origin 5 | B8: =(Reserves!D9-Reserves!F9)/(Reserves!B9-Reserves!F9) -> 0.59603696
A9: Origin 6 | B9: =(Reserves!D10-Reserves!F10)/(Reserves!B10-Reserves!F10) -> 0.59331501
A10: Origin 7 | B10: =(Reserves!D11-Reserves!F11)/(Reserves!B11-Reserves!F11) -> 0.58809653
A11: Origin 8 | B11: =(Reserves!D12-Reserves!F12)/(Reserves!B12-Reserves!F12) -> 0.58067216
A12: Origin 9 | B12: =(Reserves!D13-Reserves!F13)/(Reserves!B13-Reserves!F13) -> 0.55987377
A13: Origin 10 | B13: =(Reserves!D14-Reserves!F14)/(Reserves!B14-Reserves!F14) -> 0.46590962
A14: Total | B14: =(Reserves!D15-Reserves!F15)/(Reserves!B15-Reserves!F15) -> 0.51740048

Sheet Methods
A1: Chain Ladder and Cape Cod benchmarks
A3: Chain Ladder development view | G3: Cape Cod additive loss-ratio view | L3: Cape Cod common LR
A4: Dev age | B4: f_j | C4: CDF to ult | D4: Paid proportion q_m | G4: Dev age | H4: C_j | I4: E_{n-j+1} | J4: Additive LR ell_j | K4: Cumulative paid proportion q_m | L4: =SUM(J5:J14) -> 0.67374012
A5: 1 | B5: =SUM(Inputs!C20:C28)/SUM(Inputs!B20:B28) -> 1.4925359 | C5: =PRODUCT(B5:B13) -> 1.6961091 | D5: =1/C5 -> 0.5895847 | G5: 1 | H5: =Inputs!B34 -> 58244126 | I5: =Inputs!B35 -> 1.4747372e+08 | J5: =H5/I5 -> 0.39494581 | K5: =SUM($J$5:J5)/SUM($J$5:$J$14) -> 0.58619904
A6: 2 | B6: =SUM(Inputs!D20:D27)/SUM(Inputs!C20:C27) -> 1.0777603 | C6: =PRODUCT(B6:B13) -> 1.1363942 | D6: =1/C6 -> 0.87997634 | G6: 2 | H6: =Inputs!C34 -> 25891903 | I6: =Inputs!C35 -> 1.3226335e+08 | J6: =H6/I6 -> 0.19576022 | K6: =SUM($J$5:J6)/SUM($J$5:$J$14) -> 0.8767565
A7: 3 | B7: =SUM(Inputs!E20:E26)/SUM(Inputs!D20:D26) -> 1.0228732 | C7: =PRODUCT(B7:B13) -> 1.0544035 | D7: =1/C7 -> 0.94840354 | G7: 3 | H7: =Inputs!D34 -> 5506339.1 | I7: =Inputs!D35 -> 1.1780157e+08 | J7: =H7/I7 -> 0.046742492 | K7: =SUM($J$5:J7)/SUM($J$5:$J$14) -> 0.94613413
A8: 4 | B8: =SUM(Inputs!F20:F25)/SUM(Inputs!E20:E25) -> 1.0148409 | C8: =PRODUCT(B8:B13) -> 1.0308253 | D8: =1/C8 -> 0.97009652 | G8: 4 | H8: =Inputs!E34 -> 1556790.1 | I8: =Inputs!E35 -> 1.0325121e+08 | J8: =H8/I8 -> 0.015077693 | K8: =SUM($J$5:J8)/SUM($J$5:$J$14) -> 0.96851322
A9: 5 | B9: =SUM(Inputs!G20:G24)/SUM(Inputs!F20:F24) -> 1.0069739 | C9: =PRODUCT(B9:B13) -> 1.0157506 | D9: =1/C9 -> 0.98449365 | G9: 5 | H9: =Inputs!F34 -> 895451.23 | I9: =Inputs!F35 -> 88418247 | J9: =H9/I9 -> 0.010127448 | K9: =SUM($J$5:J9)/SUM($J$5:$J$14) -> 0.98354491
A10: 6 | B10: =SUM(Inputs!H20:H23)/SUM(Inputs!G20:G23) -> 1.0051458 | C10: =PRODUCT(B10:B13) -> 1.0087159 | D10: =1/C10 -> 0.99135943 | G10: 6 | H10: =Inputs!G34 -> 357736.62 | I10: =Inputs!G35 -> 73392324 | J10: =H10/I10 -> 0.0048743057 | K10: =SUM($J$5:J10)/SUM($J$5:$J$14) -> 0.9907796
A11: 7 | B11: =SUM(Inputs!I20:I22)/SUM(Inputs!H20:H22) -> 1.0010804 | C11: =PRODUCT(B11:B13) -> 1.0035518 | D11: =1/C11 -> 0.99646076 | G11: 7 | H11: =Inputs!H34 -> 215439.36 | I11: =Inputs!H35 -> 58866951 | J11: =H11/I11 -> 0.0036597677 | K11: =SUM($J$5:J11)/SUM($J$5:$J$14) -> 0.99621162
A12: 8 | B12: =SUM(Inputs!J20:J21)/SUM(Inputs!I20:I21) -> 1.0010468 | C12: =PRODUCT(B12:B13) -> 1.0024687 | D12: =1/C12 -> 0.99753734 | G12: 8 | H12: =Inputs!I34 -> 34960.26 | I12: =Inputs!I35 -> 44812034 | J12: =H12/I12 -> 0.00078015338 | K12: =SUM($J$5:J12)/SUM($J$5:$J$14) -> 0.99736956
A13: 9 | B13: =SUM(Inputs!K20)/SUM(Inputs!J20) -> 1.0014205 | C13: =PRODUCT(B13) -> 1.0014205 | D13: =1/C13 -> 0.99858152 | G13: 9 | H13: =Inputs!J34 -> 22775.059 | I13: =Inputs!J35 -> 30355994 | J13: =H13/I13 -> 0.00075026563 | K13: =SUM($J$5:J13)/SUM($J$5:$J$14) -> 0.99848315
A14: 10 | C14: 1 | D14: 1 | G14: 10 | H14: =Inputs!K34 -> 15813.42 | I14: =Inputs!K35 -> 15473558 | J14: =H14/I14 -> 0.001021964 | K14: =SUM($J$5:J14)/SUM($J$5:$J$14) -> 1
A17: By-origin benchmark results
A18: Origin | B18: Premium | C18: Latest paid | D18: Maturity age | E18: CL q_m | F18: CL ultimate | G18: CL ultimate LR | H18: CL reserve | I18: CC q_m | J18: CC ultimate | K18: CC a-priori ultimate LR | L18: CC reserve
A19: Origin 1 | B19: =Inputs!L5 -> 15473558 | C19: =Inputs!M5 -> 11148124 | D19: 10 | E19: =INDEX($D$5:$D$14,D19) -> 1 | F19: =C19/E19 -> 11148124 | G19: =F19/B19 -> 0.72046284 | H19: =F19-C19 -> 0 | I19: =INDEX($K$5:$K$14,D19) -> 1 | J19: =$L$4*B19 -> 10425157 | K19: =J19/B19 -> 0.67374012 | L19: =J19* (1-I19) -> 0
A20: Origin 2 | B20: =Inputs!L6 -> 14882436 | C20: =Inputs!M6 -> 10648192 | D20: 9 | E20: =INDEX($D$5:$D$14,D20) -> 0.99858152 | F20: =C20/E20 -> 10663318 | G20: =F20/B20 -> 0.7165035 | H20: =F20-C20 -> 15125.731 | I20: =INDEX($K$5:$K$14,D20) -> 0.99848315 | J20: =$L$4*B20 -> 10026894 | K20: =J20/B20 -> 0.67374012 | L20: =J20* (1-I20) -> 15209.314
A21: Origin 3 | B21: =Inputs!L7 -> 14456039 | C21: =Inputs!M7 -> 10635751 | D21: 8 | E21: =INDEX($D$5:$D$14,D21) -> 0.99753734 | F21: =C21/E21 -> 10662008 | G21: =F21/B21 -> 0.73754696 | H21: =F21-C21 -> 26256.923 | I21: =INDEX($K$5:$K$14,D21) -> 0.99736956 | J21: =$L$4*B21 -> 9739613.7 | K21: =J21/B21 -> 0.67374012 | L21: =J21* (1-I21) -> 25619.422
A22: Origin 4 | B22: =Inputs!L8 -> 14054917 | C22: =Inputs!M8 -> 9724068.2 | D22: 7 | E22: =INDEX($D$5:$D$14,D22) -> 0.99646076 | F22: =C22/E22 -> 9758606.3 | G22: =F22/B22 -> 0.69431972 | H22: =F22-C22 -> 34538.068 | I22: =INDEX($K$5:$K$14,D22) -> 0.99621162 | J22: =$L$4*B22 -> 9469361.7 | K22: =J22/B22 -> 0.67374012 | L22: =J22* (1-I22) -> 35873.533
A23: Origin 5 | B23: =Inputs!L9 -> 14525373 | C23: =Inputs!M9 -> 9786916.1 | D23: 6 | E23: =INDEX($D$5:$D$14,D23) -> 0.99135943 | F23: =C23/E23 -> 9872217.6 | G23: =F23/B23 -> 0.67965331 | H23: =F23-C23 -> 85301.539 | I23: =INDEX($K$5:$K$14,D23) -> 0.9907796 | J23: =$L$4*B23 -> 9786326.3 | K23: =J23/B23 -> 0.67374012 | L23: =J23* (1-I23) -> 90233.804
A24: Origin 6 | B24: =Inputs!L10 -> 15025923 | C24: =Inputs!M10 -> 9935753 | D24: 5 | E24: =INDEX($D$5:$D$14,D24) -> 0.98449365 | F24: =C24/E24 -> 10092247 | G24: =F24/B24 -> 0.67165568 | H24: =F24-C24 -> 156493.89 | I24: =INDEX($K$5:$K$14,D24) -> 0.98354491 | J24: =$L$4*B24 -> 10123567 | K24: =J24/B24 -> 0.67374012 | L24: =J24* (1-I24) -> 166584.25
A25: Origin 7 | B25: =Inputs!L11 -> 14832965 | C25: =Inputs!M11 -> 9282022.2 | D25: 4 | E25: =INDEX($D$5:$D$14,D25) -> 0.97009652 | F25: =C25/E25 -> 9568142.9 | G25: =F25/B25 -> 0.64505935 | H25: =F25-C25 -> 286120.73 | I25: =INDEX($K$5:$K$14,D25) -> 0.96851322 | J25: =$L$4*B25 -> 9993563.8 | K25: =J25/B25 -> 0.67374012 | L25: =J25* (1-I25) -> 314665.11
A26: Origin 8 | B26: =Inputs!L12 -> 14550359 | C26: =Inputs!M12 -> 8256211.4 | D26: 3 | E26: =INDEX($D$5:$D$14,D26) -> 0.94840354 | F26: =C26/E26 -> 8705378.1 | G26: =F26/B26 -> 0.59829301 | H26: =F26-C26 -> 449166.73 | I26: =INDEX($K$5:$K$14,D26) -> 0.94613413 | J26: =$L$4*B26 -> 9803160.7 | K26: =J26/B26 -> 0.67374012 | L26: =J26* (1-I26) -> 528055.78
A27: Origin 9 | B27: =Inputs!L13 -> 14461781 | C27: =Inputs!M13 -> 7648728.9 | D27: 2 | E27: =INDEX($D$5:$D$14,D27) -> 0.87997634 | F27: =C27/E27 -> 8691971.1 | G27: =F27/B27 -> 0.60103046 | H27: =F27-C27 -> 1043242.2 | I27: =INDEX($K$5:$K$14,D27) -> 0.8767565 | J27: =$L$4*B27 -> 9743482.3 | K27: =J27/B27 -> 0.67374012 | L27: =J27* (1-I27) -> 1200820.8
A28: Origin 10 | B28: =Inputs!L14 -> 15210363 | C28: =Inputs!M14 -> 5675568.1 | D28: 1 | E28: =INDEX($D$5:$D$14,D28) -> 0.5895847 | F28: =C28/E28 -> 9626383 | G28: =F28/B28 -> 0.63288319 | H28: =F28-C28 -> 3950814.8 | I28: =INDEX($K$5:$K$14,D28) -> 0.58619904 | J28: =$L$4*B28 -> 10247832 | K28: =J28/B28 -> 0.67374012 | L28: =J28* (1-I28) -> 4240562.6

Sheet Tau_Grid
A1: MAP tau grid search
A3: Max tau | B3: 5000
A4: Step | B4: 0.5
A5: MAP tau | B5: =INDEX(B9:B10008,MATCH(MAX(C9:C10008),C9:C10008,0)) -> 346
A6: Max log posterior | B6: =MAX(C9:C10008) -> -9620.7692
A8: Index | B8: Tau | C8: Log Likelihood | D8: Likelihood (Normalized) | E8: Term OY2 | F8: Term OY3 | G8: Term OY4 | H8: Term OY5 | I8: Term OY6 | J8: Term OY7 | K8: Term OY8 | L8: Term OY9 | M8: Term OY10
A9: =ROW()-8 -> 1 | B9: =IF((ROW()-8)*$B$4<=$B$3,(ROW()-8)*$B$4,"") -> 0.5 | C9: =IF(B9="","",SUM(E9:M9)) -> -9644.6338 | D9: =EXP(C9-$B$6) -> 4.3226246e-11 | E9: {=GAMMALN((1+Hierarchical!$F$10+B9:B10008*Hierarchical!$D$9))+GAMMALN((Hierarchical!$E$10+B9:B10008*Hierarchical!$C$10))-GAMMALN((1+Hierarchical!$F$10+B9:B10008*Hierarchical!$D$9)+(Hierarchical!$E$10+B9:B10008*Hierarchical!$C$10))-GAMMALN((1+B9:B10008*Hierarchical!$D$9))-GAMMALN((B9:B10008*Hierarchical!$C$10))+GAMMALN((1+B9:B10008*Hierarchical!$D$10))} -> -702.03445 | F9: {=GAMMALN((1+Hierarchical!$F$11+B9:B10008*Hierarchical!$D$10))+GAMMALN((Hierarchical!$E$11+B9:B10008*Hierarchical!$C$11))-GAMMALN((1+Hierarchical!$F$11+B9:B10008*Hierarchical!$D$10)+(Hierarchical!E$11+B9:B10008*Hierarchical!$C$11))-GAMMALN((1+B9:B10008*Hierarchical!$D$10))-GAMMALN((B9:B10008*Hierarchical!$C$11))+GAMMALN((1+B9:B10008*Hierarchical!$D$11))} -> -952.49042 | G9: {=GAMMALN((1+Hierarchical!$F$12+B9:B10008*Hierarchical!$D$11))+GAMMALN((Hierarchical!$E$12+B9:B10008*Hierarchical!$C$12))-GAMMALN((1+Hierarchical!$F$12+B9:B10008*Hierarchical!$D$11)+(Hierarchical!$E$12+B9:B10008*Hierarchical!C12))-GAMMALN((1+B9:B10008*Hierarchical!$D$11))-GAMMALN((B9:B10008*Hierarchical!$C$12))+GAMMALN((1+B9:B10008*Hierarchical!$D$12))} -> -1056.2666 | H9: {=GAMMALN((1+Hierarchical!F13+B9:B10008*Hierarchical!$D$12))+GAMMALN((Hierarchical!E13+B9:B10008*Hierarchical!C13))-GAMMALN((1+Hierarchical!F13+B9:B10008*Hierarchical!$D$12)+(Hierarchical!E13+B9:B10008*Hierarchical!C13))-GAMMALN((1+B9:B10008*Hierarchical!$D$12))-GAMMALN((B9:B10008*Hierarchical!C13))+GAMMALN((1+B9:B10008*Hierarchical!$D$13))} -> -1163.9309 | I9: {=GAMMALN((1+Hierarchical!F14+B9:B10008*Hierarchical!$D$13))+GAMMALN((Hierarchical!E14+B9:B10008*Hierarchical!C14))-GAMMALN((1+Hierarchical!F14+B9:B10008*Hierarchical!$D$13)+(Hierarchical!E14+B9:B10008*Hierarchical!C14))-GAMMALN((1+B9:B10008*Hierarchical!$D$13))-GAMMALN((B9:B10008*Hierarchical!C14))+GAMMALN((1+B9:B10008*Hierarchical!$D$14))} -> -1259.928 | J9: {=GAMMALN((1+Hierarchical!F15+B9:B10008*Hierarchical!$D$14))+GAMMALN((Hierarchical!E15+B9:B10008*Hierarchical!C15))-GAMMALN((1+Hierarchical!F15+B9:B10008*Hierarchical!$D$14)+(Hierarchical!E15+B9:B10008*Hierarchical!C15))-GAMMALN((1+B9:B10008*Hierarchical!$D$14))-GAMMALN((B9:B10008*Hierarchical!C15))+GAMMALN((1+B9:B10008*Hierarchical!$D$15))} -> -1268.5066 | K9: {=GAMMALN((1+Hierarchical!F16+B9:B10008*Hierarchical!$D$15))+GAMMALN((Hierarchical!E16+B9:B10008*Hierarchical!C16))-GAMMALN((1+Hierarchical!F16+B9:B10008*Hierarchical!$D$15)+(Hierarchical!E16+B9:B10008*Hierarchical!C16))-GAMMALN((1+B9:B10008*Hierarchical!$D$15))-GAMMALN((B9:B10008*Hierarchical!C16))+GAMMALN((1+B9:B10008*Hierarchical!$D$16))} -> -1213.7344 | L9: {=GAMMALN((1+Hierarchical!F17+B9:B10008*Hierarchical!$D$16))+GAMMALN((Hierarchical!E17+B9:B10008*Hierarchical!C17))-GAMMALN((1+Hierarchical!F17+B9:B10008*Hierarchical!$D$16)+(Hierarchical!E17+B9:B10008*Hierarchical!C17))-GAMMALN((1+B9:B10008*Hierarchical!$D$16))-GAMMALN((B9:B10008*Hierarchical!C17))+GAMMALN((1+B9:B10008*Hierarchical!$D$17))} -> -1163.5353 | M9: {=GAMMALN((1+Hierarchical!F18+B9:B10008*Hierarchical!$D$17))+GAMMALN((Hierarchical!E18+B9:B10008*Hierarchical!C18))-GAMMALN((1+Hierarchical!F18+B9:B10008*Hierarchical!$D$17)+(Hierarchical!E18+B9:B10008*Hierarchical!C18))-GAMMALN((1+B9:B10008*Hierarchical!$D$17))-GAMMALN((B9:B10008*Hierarchical!C18))+GAMMALN((1+B9:B10008*Hierarchical!$D$18))} -> -864.20705
A10: =ROW()-8 -> 2 | B10: =IF((ROW()-8)*$B$4<=$B$3,(ROW()-8)*$B$4,"") -> 1 | C10: =IF(B10="","",SUM(E10:M10)) -> -9640.7881 | D10: =EXP(C10-$B$6) -> 2.0225093e-09 | E10: -701.58179 | F10: -952.05569 | G10: -1055.8362 | H10: -1163.5051 | I10: -1259.5056 | J10: -1268.0852 | K10: -1213.3154 | L10: -1163.1152 | M10: -863.78792
A11: =ROW()-8 -> 3 | B11: =IF((ROW()-8)*$B$4<=$B$3,(ROW()-8)*$B$4,"") -> 1.5 | C11: =IF(B11="","",SUM(E11:M11)) -> -9638.7091 | D11: =EXP(C11-$B$6) -> 1.6172642e-08 | E11: -701.34003 | F11: -951.82122 | G11: -1055.6035 | H11: -1163.2743 | I11: -1259.276 | J11: -1267.8565 | K11: -1213.0895 | L11: -1162.8881 | M11: -863.55999
A12: =ROW()-8 -> 4 | B12: =IF((ROW()-8)*$B$4<=$B$3,(ROW()-8)*$B$4,"") -> 2 | C12: =IF(B12="","",SUM(E12:M12)) -> -9637.2919 | D12: =EXP(C12-$B$6) -> 6.6725473e-08 | E12: -701.17625 | F12: -951.66135 | G12: -1055.4446 | H12: -1163.1165 | I12: -1259.119 | J12: -1267.7004 | K12: -1212.9362 | L12: -1162.7336 | M12: -863.40407
A13: =ROW()-8 -> 5 | B13: =IF((ROW()-8)*$B$4<=$B$3,(ROW()-8)*$B$4,"") -> 2.5 | C13: =IF(B13="","",SUM(E13:M13)) -> -9636.2198 | D13: =EXP(C13-$B$6) -> 1.9493861e-07 | E13: -701.05273 | F13: -951.54027 | G13: -1055.3242 | H13: -1162.9968 | I13: -1258.9998 | J13: -1267.5821 | K13: -1212.8208 | L13: -1162.6171 | M13: -863.28587
A14: =ROW()-8 -> 6 | B14: =IF((ROW()-8)*$B$4<=$B$3,(ROW()-8)*$B$4,"") -> 3 | C14: =IF(B14="","",SUM(E14:M14)) -> -9635.3592 | D14: =EXP(C14-$B$6) -> 4.6091654e-07 | E14: -700.9537 | F14: -951.44291 | G14: -1055.2273 | H14: -1162.9006 | I14: -1258.904 | J14: -1267.4872 | K14: -1212.7287 | L14: -1162.524 | M14: -863.19085
A15: =ROW()-8 -> 7 | B15: =IF((ROW()-8)*$B$4<=$B$3,(ROW()-8)*$B$4,"") -> 3.5 | C15: =IF(B15="","",SUM(E15:M15)) -> -9634.6415 | D15: =EXP(C15-$B$6) -> 9.4473693e-07 | E15: -700.87111 | F15: -951.36156 | G15: -1055.1464 | H15: -1162.8202 | I15: -1258.8238 | J15: -1267.4079 | K15: -1212.6524 | L15: -1162.4465 | M15: -863.1115
A16: =ROW()-8 -> 8 | B16: =IF((ROW()-8)*$B$4<=$B$3,(ROW()-8)*$B$4,"") -> 4 | C16: =IF(B16="","",SUM(E16:M16)) -> -9634.0267 | D16: =EXP(C16-$B$6) -> 1.7470993e-06 | E16: -700.80033 | F16: -951.29172 | G16: -1055.077 | H16: -1162.7512 | I16: -1258.7551 | J16: -1267.3401 | K16: -1212.5875 | L16: -1162.3805 | M16: -863.04346
A17: =ROW()-8 -> 9 | B17: =IF((ROW()-8)*$B$4<=$B$3,(ROW()-8)*$B$4,"") -> 4.5 | C17: =IF(B17="","",SUM(E17:M17)) -> -9633.4896 | D17: =EXP(C17-$B$6) -> 2.9896213e-06 | E17: -700.73841 | F17: -951.23056 | G17: -1055.0162 | H17: -1162.6908 | I17: -1258.6948 | J17: -1267.2808 | K17: -1212.5311 | L17: -1162.323 | M17: -862.98396
A18: =ROW()-8 -> 10 | B18: =IF((ROW()-8)*$B$4<=$B$3,(ROW()-8)*$B$4,"") -> 5 | C18: =IF(B18="","",SUM(E18:M18)) -> -9633.013 | D18: =EXP(C18-$B$6) -> 4.8148641e-06 | E18: -700.6834 | F18: -951.17618 | G18: -1054.9621 | H18: -1162.6371 | I18: -1258.6413 | J18: -1267.2281 | K18: -1212.4814 | L18: -1162.2722 | M18: -862.93115
A19: =ROW()-8 -> 11 | B19: =IF((ROW()-8)*$B$4<=$B$3,(ROW()-8)*$B$4,"") -> 5.5 | C19: =IF(B19="","",SUM(E19:M19)) -> -9632.5851 | D19: =EXP(C19-$B$6) -> 7.3861464e-06 | E19: -700.63392 | F19: -951.12723 | G19: -1054.9135 | H19: -1162.5888 | I19: -1258.5932 | J19: -1267.1809 | K19: -1212.4371 | L19: -1162.2268 | M19: -862.88369
A20: =ROW()-8 -> 12 | B20: =IF((ROW()-8)*$B$4<=$B$3,(ROW()-8)*$B$4,"") -> 6 | C20: =IF(B20="","",SUM(E20:M20)) -> -9632.1971 | D20: =EXP(C20-$B$6) -> 1.0887189e-05 | E20: -700.58898 | F20: -951.08274 | G20: -1054.8693 | H20: -1162.5449 | I20: -1258.5495 | J20: -1267.1381 | K20: -1212.3972 | L20: -1162.1857 | M20: -862.84064
A21: =ROW()-8 -> 13 | B21: =IF((ROW()-8)*$B$4<=$B$3,(ROW()-8)*$B$4,"") -> 6.5 | C21: =IF(B21="","",SUM(E21:M21)) -> -9631.8425 | D21: =EXP(C21-$B$6) -> 1.5521628e-05 | E21: -700.54782 | F21: -951.04198 | G21: -1054.8288 | H21: -1162.5048 | I21: -1258.5094 | J21: -1267.099 | K21: -1212.361 | L21: -1162.1484 | M21: -862.80127
... A10008: =ROW()-8 -> 10000 | B10008: =IF((ROW()-8)*$B$4<=$B$3,(ROW()-8)*$B$4,"") -> 5000 | C10008: =IF(B10008="","",SUM(E10008:M10008)) -> -9622.3371 | D10008: =EXP(C10008-$B$6) -> 0.20848823 | E10008: -698.39201 | F10008: -948.96957 | G10008: -1052.9778 | H10008: -1160.8676 | I10008: -1256.9323 | J10008: -1266.2941 | K10008: -1213.9158 | L10008: -1162.5965 | M10008: -861.39141

Sheet Hierarchical
A1: Hierarchical origin-side model
A3: MAP tau from grid | B3: =Tau_Grid!B5 -> 346
A4: User override tau
A5: Selected tau | B5: =IF(B4="",B3,B4) -> 346
A6: Set B4 to 0 to recover the exact Chain Ladder endpoint. | B6: Selected phi is Inputs!B42 and defaults to the CC ODP Pearson estimate.
O7: Expected future cell means C_j m_ij
A8: Origin | B8: Premium | C8: Index | D8: Cumulative Index | E8: Scaled latest paid d_i | F8: Scaled S_i | G8: u_i(tau) | H8: v_i(tau) | I8: A_i | J8: R_i | K8: Reserve (actual) | L8: Posterior mean ultimate (actual) | M8: Posterior mean ultimate LR | O8: Dev 1 | P8: Dev 2 | Q8: Dev 3 | R8: Dev 4 | S8: Dev 5 | T8: Dev 6 | U8: Dev 7 | V8: Dev 8 | W8: Dev 9 | X8: Dev 10 | Z8: v_i | AA8: v_i^(2) | AB8: Scaled reserve variance | AC8: Reserve Variance
A9: Origin 1 | B9: =Inputs!L5 -> 15473558 | C9: =B9/$B$9 -> 1 | D9: =C9 -> 1 | E9: =Inputs!L58 -> 515.85792 | K9: =SUM(O9:X9)*Inputs!$B$42 -> 0 | L9: =Inputs!M5+K9 -> 11148124 | M9: =L9/B9 -> 0.72046284 | N9: Origin 1
A10: Origin 2 | B10: =Inputs!L6 -> 14882436 | C10: =B10/$B$9 -> 0.96179791 | D10: =C10+D9 -> 1.9617979 | E10: =Inputs!L59 -> 492.72453 | F10: =SUM(Inputs!J71) -> 515.12618 | G10: =1+F10+$B$5*D9 -> 862.12618 | H10: =E10+$B$5*C10 -> 825.50661 | I10: =H10/(G10-1) -> 0.95863605 | J10: =(G10+H10-1)/(G10-1) -> 1.9586361 | K10: =SUM(O10:X10)*Inputs!$B$42 -> 15159.315 | L10: =Inputs!M6+K10 -> 10663351 | M10: =L10/B10 -> 0.71650576 | N10: Origin 2 | X10: =Inputs!K85*$I$10 -> 0.70146803 | Z10: =(G10+H10-1)/(G10-1) -> 1.9586361 | AA10: =((G10+H10-1)*(G10+H10-2))/((G10-1)*(G10-2)) -> 3.8384381 | AB10: =SUMPRODUCT(O10:X10,1+AD10:AM10)+SUMPRODUCT(AN10:AW10,2*AX10:BG10-O10:X10) -> 1.3766868 | AC10: =AB10*Inputs!$B$42^2 -> 6.4295192e+08 | AM10: =($H$10+1)/($G$10-2) -> 0.9609132 | AW10: =IF(X10="","",Inputs!K85*AM10-X10) -> 0.0016662712 | BG10: =IF(X10="","",X10) -> 0.70146803
A11: Origin 3 | B11: =Inputs!L7 -> 14456039 | C11: =B11/$B$9 -> 0.93424144 | D11: =C11+D10 -> 2.8960393 | E11: =Inputs!L60 -> 492.14886 | F11: =SUM(Inputs!I71:I72) -> 1006.7968 | G11: =1+F11+$B$5*D10 -> 1686.5789 | H11: =E11+$B$5*C11 -> 815.39639 | I11: =H11/(G11-1) -> 0.48374857 | J11: =(G11+H11-1)/(G11-1) -> 1.4837486 | K11: =SUM(O11:X11)*Inputs!$B$42 -> 26000.418 | L11: =Inputs!M7+K11 -> 10661751 | M11: =L11/B11 -> 0.73752922 | N11: Origin 3 | W11: =Inputs!J85*$I$11 -> 0.50980904 | X11: =Inputs!K85*$I$11*$J$10 -> 0.69331016 | Z11: =(G11+H11-1)/(G11-1) -> 1.4837486 | AA11: =((G11+H11-1)*(G11+H11-2))/((G11-1)*(G11-2)) -> 2.2019359 | AB11: =SUMPRODUCT(O11:X11,1+AD11:AM11)+SUMPRODUCT(AN11:AW11,2*AX11:BG11-O11:X11) -> 2.1115703 | AC11: =AB11*Inputs!$B$42^2 -> 9.8616347e+08 | AL11: =($H$11+1)/($G$11-2) -> 0.48462935 | AM11: =AL11*($AA$10/$Z$10) -> 0.94975266 | AV11: =IF(W11="","",Inputs!J85*AL11-W11) -> 0.00092823253 | AW11: =IF(X11="","",Inputs!K85*AM11-X11) -> 0.0016575764 | BF11: =IF(W11="","",W11+BG11) -> 1.2031192 | BG11: =IF(X11="","",X11) -> 0.69331016
A12: Origin 4 | B12: =Inputs!L8 -> 14054917 | C12: =B12/$B$9 -> 0.90831838 | D12: =C12+D11 -> 3.8043577 | E12: =Inputs!L61 -> 449.96249 | F12: =SUM(Inputs!H71:H73) -> 1497.328 | G12: =1+F12+$B$5*D11 -> 2500.3576 | H12: =E12+$B$5*C12 -> 764.24065 | I12: =H12/(G12-1) -> 0.30577483 | J12: =(G12+H12-1)/(G12-1) -> 1.3057748 | K12: =SUM(O12:X12)*Inputs!$B$42 -> 35074.964 | L12: =Inputs!M8+K12 -> 9759143.2 | M12: =L12/B12 -> 0.69435792 | N12: Origin 4 | V12: =Inputs!I85*$I$12 -> 0.49465763 | W12: =Inputs!J85*$I$12*$J$11 -> 0.47813428 | X12: =Inputs!K85*$I$12*$J$10*$J$11 -> 0.65023437 | Z12: =(G12+H12-1)/(G12-1) -> 1.3057748 | AA12: =((G12+H12-1)*(G12+H12-2))/((G12-1)*(G12-2)) -> 1.7052077 | AB12: =SUMPRODUCT(O12:X12,1+AD12:AM12)+SUMPRODUCT(AN12:AW12,2*AX12:BG12-O12:X12) -> 2.5761081 | AC12: =AB12*Inputs!$B$42^2 -> 1.2031158e+09 | AK12: =($H$12+1)/($G$12-2) -> 0.30629749 | AL12: =AK12*($AA$11/$Z$11) -> 0.45455642 | AM12: =AL12*($AA$10/$Z$10) -> 0.8908172 | AU12: =IF(V12="","",Inputs!I85*AK12-V12) -> 0.00084550594 | AV12: =IF(W12="","",Inputs!J85*AL12-W12) -> 0.00090995871 | AW12: =IF(X12="","",Inputs!K85*AM12-X12) -> 0.0016081994 | BE12: =IF(V12="","",V12+BF12) -> 1.6230263 | BF12: =IF(W12="","",W12+BG12) -> 1.1283687 | BG12: =IF(X12="","",X12) -> 0.65023437
A13: Origin 5 | B13: =Inputs!L9 -> 14525373 | C13: =B13/$B$9 -> 0.93872219 | D13: =C13+D12 -> 4.7430799 | E13: =Inputs!L62 -> 452.87066 | F13: =SUM(Inputs!G71:G74) -> 1937.3214 | G13: =1+F13+$B$5*D12 -> 3254.6292 | H13: =E13+$B$5*C13 -> 777.66854 | I13: =H13/(G13-1) -> 0.23901572 | J13: =(G13+H13-1)/(G13-1) -> 1.2390157 | K13: =SUM(O13:X13)*Inputs!$B$42 -> 87293.991 | L13: =Inputs!M9+K13 -> 9874210 | M13: =L13/B13 -> 0.67979048 | N13: Origin 5 | U13: =Inputs!H85*$I$13 -> 2.3827575 | V13: =Inputs!I85*$I$13*$J$12 -> 0.50489112 | W13: =Inputs!J85*$I$13*$J$11*$J$12 -> 0.48802594 | X13: =Inputs!K85*$I$13*$J$10*$J$11*$J$12 -> 0.66368644 | Z13: =(G13+H13-1)/(G13-1) -> 1.2390157 | AA13: =((G13+H13-1)*(G13+H13-2))/((G13-1)*(G13-2)) -> 1.535251 | AB13: =SUMPRODUCT(O13:X13,1+AD13:AM13)+SUMPRODUCT(AN13:AW13,2*AX13:BG13-O13:X13) -> 5.6242592 | AC13: =AB13*Inputs!$B$42^2 -> 2.6266892e+09 | AJ13: =($H$13+1)/($G$13-2) -> 0.23939665 | AK13: =AJ13*($AA$12/$Z$12) -> 0.31262742 | AL13: =AK13*($AA$11/$Z$11) -> 0.46395026 | AM13: =AL13*($AA$10/$Z$10) -> 0.9092268 | AT13: =IF(U13="","",Inputs!H85*AJ13-U13) -> 0.0037974812 | AU13: =IF(V13="","",Inputs!I85*AK13-V13) -> 0.00085206095 | AV13: =IF(W13="","",Inputs!J85*AL13-W13) -> 0.0009182104 | AW13: =IF(X13="","",Inputs!K85*AM13-X13) -> 0.0016270823 | BD13: =IF(U13="","",U13+BE13) -> 4.039361 | BE13: =IF(V13="","",V13+BF13) -> 1.6566035 | BF13: =IF(W13="","",W13+BG13) -> 1.1517124 | BG13: =IF(X13="","",X13) -> 0.66368644
A14: Origin 6 | B14: =Inputs!L10 -> 15025923 | C14: =B14/$B$9 -> 0.97107098 | D14: =C14+D13 -> 5.7141509 | E14: =Inputs!L63 -> 459.7578 | F14: =SUM(Inputs!F71:F75) -> 2373.6385 | G14: =1+F14+$B$5*D13 -> 4015.7442 | H14: =E14+$B$5*C14 -> 795.74836 | I14: =H14/(G14-1) -> 0.19820649 | J14: =(G14+H14-1)/(G14-1) -> 1.1982065 | K14: =SUM(O14:X14)*Inputs!$B$42 -> 160597.49 | L14: =Inputs!M10+K14 -> 10096350 | M14: =L14/B14 -> 0.67192878 | N14: Origin 6 | T14: =Inputs!G85*$I$14 -> 3.2810254 | U14: =Inputs!H85*$I$14*$J$13 -> 2.4482066 | V14: =Inputs!I85*$I$14*$J$12*$J$13 -> 0.51875937 | W14: =Inputs!J85*$I$14*$J$11*$J$12*$J$13 -> 0.50143095 | X14: =Inputs!K85*$I$14*$J$10*$J$11*$J$12*$J$13 -> 0.68191645 | Z14: =(G14+H14-1)/(G14-1) -> 1.1982065 | AA14: =((G14+H14-1)*(G14+H14-2))/((G14-1)*(G14-2)) -> 1.435758 | AB14: =SUMPRODUCT(O14:X14,1+AD14:AM14)+SUMPRODUCT(AN14:AW14,2*AX14:BG14-O14:X14) -> 9.8125008 | AC14: =AB14*Inputs!$B$42^2 -> 4.5827173e+09 | AI14: =($H$14+1)/($G$14-2) -> 0.19850502 | AJ14: =AI14*($AA$13/$Z$13) -> 0.24596542 | AK14: =AJ14*($AA$12/$Z$12) -> 0.32120557 | AL14: =AK14*($AA$11/$Z$11) -> 0.47668054 | AM14: =AL14*($AA$10/$Z$10) -> 0.93417496 | AS14: =IF(T14="","",Inputs!G85*AI14-T14) -> 0.0049416696 | AT14: =IF(U14="","",Inputs!H85*AJ14-U14) -> 0.003832749 | AU14: =IF(V14="","",Inputs!I85*AK14-V14) -> 0.00086083453 | AV14: =IF(W14="","",Inputs!J85*AL14-W14) -> 0.00092928694 | AW14: =IF(X14="","",Inputs!K85*AM14-X14) -> 0.0016525278 | BC14: =IF(T14="","",T14+BD14) -> 7.4313388 | BD14: =IF(U14="","",U14+BE14) -> 4.1503134 | BE14: =IF(V14="","",V14+BF14) -> 1.7021068 | BF14: =IF(W14="","",W14+BG14) -> 1.1833474 | BG14: =IF(X14="","",X14) -> 0.68191645
A15: Origin 7 | B15: =Inputs!L11 -> 14832965 | C15: =B15/$B$9 -> 0.95860079 | D15: =C15+D14 -> 6.6727517 | E15: =Inputs!L64 -> 429.50767 | F15: =SUM(Inputs!E71:E76) -> 2791.961 | G15: =1+F15+$B$5*D14 -> 4770.0572 | H15: =E15+$B$5*C15 -> 761.18354 | I15: =H15/(G15-1) -> 0.15960881 | J15: =(G15+H15-1)/(G15-1) -> 1.1596088 | K15: =SUM(O15:X15)*Inputs!$B$42 -> 297878.26 | L15: =Inputs!M11+K15 -> 9579900.5 | M15: =L15/B15 -> 0.64585201 | N15: Origin 7 | S15: =Inputs!F85*$I$15 -> 6.6134353 | T15: =Inputs!G85*$I$15*$J$14 -> 3.1657764 | U15: =Inputs!H85*$I$15*$J$13*$J$14 -> 2.3622112 | V15: =Inputs!I85*$I$15*$J$12*$J$13*$J$14 -> 0.50053748 | W15: =Inputs!J85*$I$15*$J$11*$J$12*$J$13*$J$14 -> 0.48381773 | X15: =Inputs!K85*$I$15*$J$10*$J$11*$J$12*$J$13*$J$14 -> 0.65796352 | Z15: =(G15+H15-1)/(G15-1) -> 1.1596088 | AA15: =((G15+H15-1)*(G15+H15-2))/((G15-1)*(G15-2)) -> 1.3447314 | AB15: =SUMPRODUCT(O15:X15,1+AD15:AM15)+SUMPRODUCT(AN15:AW15,2*AX15:BG15-O15:X15) -> 17.272043 | AC15: =AB15*Inputs!$B$42^2 -> 8.0665361e+09 | AH15: =($H$15+1)/($G$15-2) -> 0.15985201 | AI15: =AH15*($AA$14/$Z$14) -> 0.19154361 | AJ15: =AI15*($AA$13/$Z$13) -> 0.23733962 | AK15: =AJ15*($AA$12/$Z$12) -> 0.30994115 | AL15: =AK15*($AA$11/$Z$11) -> 0.45996375 | AM15: =AL15*($AA$10/$Z$10) -> 0.90141422 | AR15: =IF(S15="","",Inputs!F85*AH15-S15) -> 0.01007721 | AS15: =IF(T15="","",Inputs!G85*AI15-T15) -> 0.0049545166 | AT15: =IF(U15="","",Inputs!H85*AJ15-U15) -> 0.0038372354 | AU15: =IF(V15="","",Inputs!I85*AK15-V15) -> 0.00086007733 | AV15: =IF(W15="","",Inputs!J85*AL15-W15) -> 0.00092514605 | AW15: =IF(X15="","",Inputs!K85*AM15-X15) -> 0.0016332632 | BB15: =IF(S15="","",S15+BC15) -> 13.783742 | BC15: =IF(T15="","",T15+BD15) -> 7.1703063 | BD15: =IF(U15="","",U15+BE15) -> 4.0045299 | BE15: =IF(V15="","",V15+BF15) -> 1.6423187 | BF15: =IF(W15="","",W15+BG15) -> 1.1417813 | BG15: =IF(X15="","",X15) -> 0.65796352
A16: Origin 8 | B16: =Inputs!L12 -> 14550359 | C16: =B16/$B$9 -> 0.94033698 | D16: =C16+D15 -> 7.6130887 | E16: =Inputs!L65 -> 382.04025 | F16: =SUM(Inputs!D71:D77) -> 3149.4313 | G16: =1+F16+$B$5*D15 -> 5459.2033 | H16: =E16+$B$5*C16 -> 707.39685 | I16: =H16/(G16-1) -> 0.12960251 | J16: =(G16+H16-1)/(G16-1) -> 1.1296025 | K16: =SUM(O16:X16)*Inputs!$B$42 -> 482247.11 | L16: =Inputs!M12+K16 -> 8738458.5 | M16: =L16/B16 -> 0.60056652 | N16: Origin 8 | R16: =Inputs!E85*$I$16 -> 9.3362352 | S16: =Inputs!F85*$I$16*$J$15 -> 6.2272338 | T16: =Inputs!G85*$I$16*$J$14*$J$15 -> 2.9809062 | U16: =Inputs!H85*$I$16*$J$13*$J$14*$J$15 -> 2.2242663 | V16: =Inputs!I85*$I$16*$J$12*$J$13*$J$14*$J$15 -> 0.47130784 | W16: =Inputs!J85*$I$16*$J$11*$J$12*$J$13*$J$14*$J$15 -> 0.45556446 | X16: =Inputs!K85*$I$16*$J$10*$J$11*$J$12*$J$13*$J$14*$J$15 -> 0.61954075 | Z16: =(G16+H16-1)/(G16-1) -> 1.1296025 | AA16: =((G16+H16-1)*(G16+H16-2))/((G16-1)*(G16-2)) -> 1.2760287 | AB16: =SUMPRODUCT(O16:X16,1+AD16:AM16)+SUMPRODUCT(AN16:AW16,2*AX16:BG16-O16:X16) -> 27.163572 | AC16: =AB16*Inputs!$B$42^2 -> 1.2686162e+10 | AG16: =($H$16+1)/($G$16-2) -> 0.1298095 | AH16: =AG16*($AA$15/$Z$15) -> 0.15053259 | AI16: =AH16*($AA$14/$Z$14) -> 0.18037656 | AJ16: =AI16*($AA$13/$Z$13) -> 0.22350264 | AK16: =AJ16*($AA$12/$Z$12) -> 0.29187148 | AL16: =AK16*($AA$11/$Z$11) -> 0.43314771 | AM16: =AL16*($AA$10/$Z$10) -> 0.84886148 | AQ16: =IF(R16="","",Inputs!E85*AG16-R16) -> 0.014911244 | AR16: =IF(S16="","",Inputs!F85*AH16-S16) -> 0.010125794 | AS16: =IF(T16="","",Inputs!G85*AI16-T16) -> 0.004970155 | AT16: =IF(U16="","",Inputs!H85*AJ16-U16) -> 0.0038407237 | AU16: =IF(V16="","",Inputs!I85*AK16-V16) -> 0.00085807685 | AV16: =IF(W16="","",Inputs!J85*AL16-W16) -> 0.00091774392 | AW16: =IF(X16="","",Inputs!K85*AM16-X16) -> 0.0016013271 | BA16: =IF(R16="","",R16+BB16) -> 22.315054 | BB16: =IF(S16="","",S16+BC16) -> 12.978819 | BC16: =IF(T16="","",T16+BD16) -> 6.7515855 | BD16: =IF(U16="","",U16+BE16) -> 3.7706793 | BE16: =IF(V16="","",V16+BF16) -> 1.5464131 | BF16: =IF(W16="","",W16+BG16) -> 1.0751052 | BG16: =IF(X16="","",X16) -> 0.61954075
A17: Origin 9 | B17: =Inputs!L13 -> 14461781 | C17: =B17/$B$9 -> 0.93461251 | D17: =C17+D16 -> 8.5477012 | E17: =Inputs!L66 -> 353.93017 | F17: =SUM(Inputs!C71:C78) -> 3276.6763 | G17: =1+F17+$B$5*D16 -> 5911.805 | H17: =E17+$B$5*C17 -> 677.3061 | I17: =H17/(G17-1) -> 0.11458779 | J17: =(G17+H17-1)/(G17-1) -> 1.1145878 | K17: =SUM(O17:X17)*Inputs!$B$42 -> 1112596.7 | L17: =Inputs!M13+K17 -> 8761325.6 | M17: =L17/B17 -> 0.60582617 | N17: Origin 9 | Q17: =Inputs!D85*$I$17 -> 29.196422 | R17: =Inputs!E85*$I$17*$J$16 -> 9.3244319 | S17: =Inputs!F85*$I$17*$J$15*$J$16 -> 6.219361 | T17: =Inputs!G85*$I$17*$J$14*$J$15*$J$16 -> 2.9771376 | U17: =Inputs!H85*$I$17*$J$13*$J$14*$J$15*$J$16 -> 2.2214543 | V17: =Inputs!I85*$I$17*$J$12*$J$13*$J$14*$J$15*$J$16 -> 0.47071199 | W17: =Inputs!J85*$I$17*$J$11*$J$12*$J$13*$J$14*$J$15*$J$16 -> 0.45498852 | X17: =Inputs!K85*$I$17*$J$10*$J$11*$J$12*$J$13*$J$14*$J$15*$J$16 -> 0.6187575 | Z17: =(G17+H17-1)/(G17-1) -> 1.1145878 | AA17: =((G17+H17-1)*(G17+H17-2))/((G17-1)*(G17-2)) -> 1.2423276 | AB17: =SUMPRODUCT(O17:X17,1+AD17:AM17)+SUMPRODUCT(AN17:AW17,2*AX17:BG17-O17:X17) -> 63.250524 | AC17: =AB17*Inputs!$B$42^2 -> 2.9539796e+10 | AF17: =($H$17+1)/($G$17-2) -> 0.11477639 | AG17: =AF17*($AA$16/$Z$16) -> 0.12965443 | AH17: =AG17*($AA$15/$Z$15) -> 0.15035276 | AI17: =AH17*($AA$14/$Z$14) -> 0.18016107 | AJ17: =AI17*($AA$13/$Z$13) -> 0.22323564 | AK17: =AJ17*($AA$12/$Z$12) -> 0.29152281 | AL17: =AK17*($AA$11/$Z$11) -> 0.43263026 | AM17: =AL17*($AA$10/$Z$10) -> 0.84784741 | AP17: =IF(Q17="","",Inputs!D85*AF17-Q17) -> 0.048054316 | AQ17: =IF(R17="","",Inputs!E85*AG17-R17) -> 0.015543419 | AR17: =IF(S17="","",Inputs!F85*AH17-S17) -> 0.010547237 | AS17: =IF(T17="","",Inputs!G85*AI17-T17) -> 0.0051717481 | AT17: =IF(U17="","",Inputs!H85*AJ17-U17) -> 0.0039909888 | AU17: =IF(V17="","",Inputs!I85*AK17-V17) -> 0.0008898642 | AV17: =IF(W17="","",Inputs!J85*AL17-W17) -> 0.00094836394 | AW17: =IF(X17="","",Inputs!K85*AM17-X17) -> 0.0016425466 | AZ17: =IF(Q17="","",Q17+BA17) -> 51.483265 | BA17: =IF(R17="","",R17+BB17) -> 22.286843 | BB17: =IF(S17="","",S17+BC17) -> 12.962411 | BC17: =IF(T17="","",T17+BD17) -> 6.7430498 | BD17: =IF(U17="","",U17+BE17) -> 3.7659123 | BE17: =IF(V17="","",V17+BF17) -> 1.544458 | BF17: =IF(W17="","",W17+BG17) -> 1.073746 | BG17: =IF(X17="","",X17) -> 0.6187575
A18: Origin 10 | B18: =Inputs!L14 -> 15210363 | C18: =B18/$B$9 -> 0.98299063 | D18: =C18+D17 -> 9.5306918 | E18: =Inputs!L67 -> 262.62596 | F18: =SUM(Inputs!B71:B79) -> 2432.5086 | G18: =1+F18+$B$5*D17 -> 5391.0132 | H18: =E18+$B$5*C18 -> 602.74072 | I18: =H18/(G18-1) -> 0.11182546 | J18: =(G18+H18-1)/(G18-1) -> 1.1118255 | K18: =SUM(O18:X18)*Inputs!$B$42 -> 4105566.3 | L18: =Inputs!M14+K18 -> 9781134.5 | M18: =L18/B18 -> 0.64305727 | N18: Origin 10 | P18: =Inputs!C85*$I$18 -> 133.97785 | Q18: =Inputs!D85*$I$18*$J$17 -> 31.757496 | R18: =Inputs!E85*$I$18*$J$16*$J$17 -> 10.14236 | S18: =Inputs!F85*$I$18*$J$15*$J$16*$J$17 -> 6.7649158 | T18: =Inputs!G85*$I$18*$J$14*$J$15*$J$16*$J$17 -> 3.2382885 | U18: =Inputs!H85*$I$18*$J$13*$J$14*$J$15*$J$16*$J$17 -> 2.4163175 | V18: =Inputs!I85*$I$18*$J$12*$J$13*$J$14*$J$15*$J$16*$J$17 -> 0.51200228 | W18: =Inputs!J85*$I$18*$J$11*$J$12*$J$13*$J$14*$J$15*$J$16*$J$17 -> 0.49489956 | X18: =Inputs!K85*$I$18*$J$10*$J$11*$J$12*$J$13*$J$14*$J$15*$J$16*$J$17 -> 0.67303415 | Z18: =(G18+H18-1)/(G18-1) -> 1.1118255 | AA18: =((G18+H18-1)*(G18+H18-2))/((G18-1)*(G18-2)) -> 1.2361789 | AB18: =SUMPRODUCT(O18:X18,1+AD18:AM18)+SUMPRODUCT(AN18:AW18,2*AX18:BG18-O18:X18) -> 280.3913 | AC18: =AB18*Inputs!$B$42^2 -> 1.3095072e+11 | AE18: =($H$18+1)/($G$18-2) -> 0.11203178 | AF18: =AE18*($AA$17/$Z$17) -> 0.12487142 | AG18: =AF18*($AA$16/$Z$16) -> 0.14105804 | AH18: =AG18*($AA$15/$Z$15) -> 0.16357686 | AI18: =AH18*($AA$14/$Z$14) -> 0.19600694 | AJ18: =AI18*($AA$13/$Z$13) -> 0.24287008 | AK18: =AJ18*($AA$12/$Z$12) -> 0.31716337 | AL18: =AK18*($AA$11/$Z$11) -> 0.47068177 | AM18: =AL18*($AA$10/$Z$10) -> 0.92241887 | AO18: =IF(P18="","",Inputs!C85*AE18-P18) -> 0.2471836 | AP18: =IF(Q18="","",Inputs!D85*AF18-Q18) -> 0.059144746 | AQ18: =IF(R18="","",Inputs!E85*AG18-R18) -> 0.019102629 | AR18: =IF(S18="","",Inputs!F85*AH18-S18) -> 0.012937034 | AS18: =IF(T18="","",Inputs!G85*AI18-T18) -> 0.0063265267 | AT18: =IF(U18="","",Inputs!H85*AJ18-U18) -> 0.0048642595 | AU18: =IF(V18="","",Inputs!I85*AK18-V18) -> 0.0010787922 | AV18: =IF(W18="","",Inputs!J85*AL18-W18) -> 0.0011387407 | AW18: =IF(X18="","",Inputs!K85*AM18-X18) -> 0.0019324803 | AY18: =IF(P18="","",P18+AZ18) -> 189.97716 | AZ18: =IF(Q18="","",Q18+BA18) -> 55.999314 | BA18: =IF(R18="","",R18+BB18) -> 24.241817 | BB18: =IF(S18="","",S18+BC18) -> 14.099458 | BC18: =IF(T18="","",T18+BD18) -> 7.334542 | BD18: =IF(U18="","",U18+BE18) -> 4.0962535 | BE18: =IF(V18="","",V18+BF18) -> 1.679936 | BF18: =IF(W18="","",W18+BG18) -> 1.1679337 | BG18: =IF(X18="","",X18) -> 0.67303415
A20: Total | B20: =SUM(B9:B18) -> 1.4747372e+08 | E20: =SUM(E9:E18) -> 4291.4263 | K20: =SUM(K9:K18) -> 6322414.6 | L20: =SUM(L9:L18) -> 99063749 | M20: =L20/B20 -> 0.67173834 | AB20: =SUMPRODUCT(AC23:AC31,AB23:AB31-AA23:AA31)+SUMPRODUCT(AE23:AE31,2*AF23:AF31-AD23:AD31) -> 528.83881 | AC20: =AB20*Inputs!$B$42^2 -> 2.4698278e+11
Z22: Dev age | AA22: Pi_j | AB22: Pi_j^(2) | AC22: c_j | AD22: u_j=c_j Pi_j | AE22: b_j | AF22: cumulative_u_j
Z23: 2 | AA23: =PRODUCT($Z$18:$Z$18) -> 1.1118255 | AB23: =PRODUCT($AA$18:$AA$18) -> 1.2361789 | AC23: =Inputs!C85 -> 1198.0979 | AD23: =AC23*AA23 -> 1332.0757 | AE23: =AC23*(AB23/AA23-AA23) -> 0.024861295 | AF23: =AD23+AF24 -> 1888.8493
Z24: 3 | AA24: =PRODUCT($Z$17:$Z$18) -> 1.2392271 | AB24: =PRODUCT($AA$17:$AA$18) -> 1.5357392 | AC24: =Inputs!D85 -> 254.79522 | AD24: =AC24*AA24 -> 315.74913 | AE24: =AC24*(AB24/AA24-AA24) -> 0.011385901 | AF24: =AD24+AF25 -> 556.77358
Z25: 4 | AA25: =PRODUCT($Z$16:$Z$18) -> 1.399834 | AB25: =PRODUCT($AA$16:$AA$18) -> 1.9596472 | AC25: =Inputs!E85 -> 72.037457 | AD25: =AC25*AA25 -> 100.84048 | AE25: =AC25*(AB25/AA25-AA25) -> 0.0057564618 | AF25: =AD25+AF26 -> 241.02444
Z26: 5 | AA26: =PRODUCT($Z$15:$Z$18) -> 1.6232599 | AB26: =PRODUCT($AA$15:$AA$18) -> 2.6351991 | AC26: =Inputs!F85 -> 41.435278 | AD26: =AC26*AA26 -> 67.260224 | AE26: =AC26*(AB26/AA26-AA26) -> 0.0057812601 | AF26: =AD26+AF27 -> 140.18396
Z27: 6 | AA27: =PRODUCT($Z$14:$Z$18) -> 1.9450005 | AB27: =PRODUCT($AA$14:$AA$18) -> 3.7835081 | AC27: =Inputs!G85 -> 16.553572 | AD27: =AC27*AA27 -> 32.196706 | AE27: =AC27*(AB27/AA27-AA27) -> 0.0040944675 | AF27: =AD27+AF28 -> 72.923736
Z28: 7 | AA28: =PRODUCT($Z$13:$Z$18) -> 2.4098862 | AB28: =PRODUCT($AA$13:$AA$18) -> 5.8086346 | AC28: =Inputs!H85 -> 9.9690409 | AD28: =AC28*AA28 -> 24.024254 | AE28: =AC28*(AB28/AA28-AA28) -> 0.0044801913 | AF28: =AD28+AF29 -> 40.72703
Z29: 8 | AA29: =PRODUCT($Z$12:$Z$18) -> 3.1467688 | AB29: =PRODUCT($AA$12:$AA$18) -> 9.9049286 | AC29: =Inputs!I85 -> 1.6177186 | AD29: =AC29*AA29 -> 5.0905863 | AE29: =AC29*(AB29/AA29-AA29) -> 0.0014265538 | AF29: =AD29+AF30 -> 16.702776
Z30: 9 | AA30: =PRODUCT($Z$11:$Z$18) -> 4.6690137 | AB30: =PRODUCT($AA$11:$AA$18) -> 21.810018 | AC30: =Inputs!J85 -> 1.0538719 | AD30: =AC30*AA30 -> 4.9205424 | AE30: =AC30*(AB30/AA30-AA30) -> 0.0023314845 | AF30: =AD30+AF31 -> 11.612189
Z31: 10 | AA31: =PRODUCT($Z$10:$Z$18) -> 9.1448985 | AB31: =PRODUCT($AA$10:$AA$18) -> 83.716405 | AC31: =Inputs!K85 -> 0.7317355 | AD31: =AC31*AA31 -> 6.6916469 | AE31: =AC31*(AB31/AA31-AA31) -> 0.0069802567 | AF31: =AD31 -> 6.6916469

Sheet Chain Ladder
A1: Hierarchical origin-side model
A3: MAP tau from grid | B3: =Tau_Grid!B5 -> 346
A4: User override tau | B4: 0
A5: Selected tau | B5: =IF(B4="",B3,B4) -> 0
A6: Set B4 to 0 to recover the exact Chain Ladder endpoint. | B6: Selected phi is Inputs!B42 and defaults to the CC ODP Pearson estimate.
O7: Expected future cell means C_j m_ij
A8: Origin | B8: Premium | C8: Index | D8: Cumulative Index | E8: Scaled latest paid d_i | F8: Scaled S_i | G8: u_i(tau) | H8: v_i(tau) | I8: A_i | J8: R_i | K8: Reserve (actual) | L8: Posterior mean ultimate (actual) | M8: Posterior mean ultimate LR | O8: Dev 1 | P8: Dev 2 | Q8: Dev 3 | R8: Dev 4 | S8: Dev 5 | T8: Dev 6 | U8: Dev 7 | V8: Dev 8 | W8: Dev 9 | X8: Dev 10 | Z8: v_i | AA8: v_i^(2) | AB8: Scaled reserve variance | AC8: Reserve Variance
A9: Origin 1 | B9: =Inputs!L5 -> 15473558 | C9: =B9/$B$9 -> 1 | D9: =C9 -> 1 | E9: =Inputs!L58 -> 515.85792 | K9: =SUM(O9:X9)*Inputs!$B$42 -> 0 | L9: =Inputs!M5+K9 -> 11148124 | M9: =L9/B9 -> 0.72046284 | N9: Origin 1
A10: Origin 2 | B10: =Inputs!L6 -> 14882436 | C10: =B10/$B$9 -> 0.96179791 | D10: =C10+D9 -> 1.9617979 | E10: =Inputs!L59 -> 492.72453 | F10: =SUM(Inputs!J71) -> 515.12618 | G10: =1+F10+$B$5*D9 -> 516.12618 | H10: =E10+$B$5*C10 -> 492.72453 | I10: =H10/(G10-1) -> 0.9565123 | J10: =(G10+H10-1)/(G10-1) -> 1.9565123 | K10: =SUM(O10:X10)*Inputs!$B$42 -> 15125.731 | L10: =Inputs!M6+K10 -> 10663318 | M10: =L10/B10 -> 0.7165035 | N10: Origin 2 | X10: =Inputs!K85*$I$10 -> 0.699914 | Z10: =(G10+H10-1)/(G10-1) -> 1.9565123 | AA10: =((G10+H10-1)*(G10+H10-2))/((G10-1)*(G10-2)) -> 3.8315804 | AB10: =SUMPRODUCT(O10:X10,1+AD10:AM10)+SUMPRODUCT(AN10:AW10,2*AX10:BG10-O10:X10) -> 1.3740029 | AC10: =AB10*Inputs!$B$42^2 -> 6.4169847e+08 | AM10: =($H$10+1)/($G$10-2) -> 0.96031781 | AW10: =IF(X10="","",Inputs!K85*AM10-X10) -> 0.0027846267 | BG10: =IF(X10="","",X10) -> 0.699914
A11: Origin 3 | B11: =Inputs!L7 -> 14456039 | C11: =B11/$B$9 -> 0.93424144 | D11: =C11+D10 -> 2.8960393 | E11: =Inputs!L60 -> 492.14886 | F11: =SUM(Inputs!I71:I72) -> 1006.7968 | G11: =1+F11+$B$5*D10 -> 1007.7968 | H11: =E11+$B$5*C11 -> 492.14886 | I11: =H11/(G11-1) -> 0.48882638 | J11: =(G11+H11-1)/(G11-1) -> 1.4888264 | K11: =SUM(O11:X11)*Inputs!$B$42 -> 26256.923 | L11: =Inputs!M7+K11 -> 10662008 | M11: =L11/B11 -> 0.73754696 | N11: Origin 3 | W11: =Inputs!J85*$I$11 -> 0.5151604 | X11: =Inputs!K85*$I$11*$J$10 -> 0.69982805 | Z11: =(G11+H11-1)/(G11-1) -> 1.4888264 | AA11: =((G11+H11-1)*(G11+H11-2))/((G11-1)*(G11-2)) -> 2.2173276 | AB11: =SUMPRODUCT(O11:X11,1+AD11:AM11)+SUMPRODUCT(AN11:AW11,2*AX11:BG11-O11:X11) -> 2.1444894 | AC11: =AB11*Inputs!$B$42^2 -> 1.0015376e+09 | AL11: =($H$11+1)/($G$11-2) -> 0.49030663 | AM11: =AL11*($AA$10/$Z$10) -> 0.96020314 | AV11: =IF(W11="","",Inputs!J85*AL11-W11) -> 0.0015599893 | AW11: =IF(X11="","",Inputs!K85*AM11-X11) -> 0.0027866798 | BF11: =IF(W11="","",W11+BG11) -> 1.2149884 | BG11: =IF(X11="","",X11) -> 0.69982805
A12: Origin 4 | B12: =Inputs!L8 -> 14054917 | C12: =B12/$B$9 -> 0.90831838 | D12: =C12+D11 -> 3.8043577 | E12: =Inputs!L61 -> 449.96249 | F12: =SUM(Inputs!H71:H73) -> 1497.328 | G12: =1+F12+$B$5*D11 -> 1498.328 | H12: =E12+$B$5*C12 -> 449.96249 | I12: =H12/(G12-1) -> 0.30051031 | J12: =(G12+H12-1)/(G12-1) -> 1.3005103 | K12: =SUM(O12:X12)*Inputs!$B$42 -> 34538.068 | L12: =Inputs!M8+K12 -> 9758606.3 | M12: =L12/B12 -> 0.69431972 | N12: Origin 4 | V12: =Inputs!I85*$I$12 -> 0.48614111 | W12: =Inputs!J85*$I$12*$J$11 -> 0.47151039 | X12: =Inputs!K85*$I$12*$J$10*$J$11 -> 0.64053098 | Z12: =(G12+H12-1)/(G12-1) -> 1.3005103 | AA12: =((G12+H12-1)*(G12+H12-2))/((G12-1)*(G12-2)) -> 1.6915882 | AB12: =SUMPRODUCT(O12:X12,1+AD12:AM12)+SUMPRODUCT(AN12:AW12,2*AX12:BG12-O12:X12) -> 2.5275498 | AC12: =AB12*Inputs!$B$42^2 -> 1.1804377e+09 | AK12: =($H$12+1)/($G$12-2) -> 0.30137944 | AL12: =AK12*($AA$11/$Z$11) -> 0.44884814 | AM12: =AL12*($AA$10/$Z$10) -> 0.87901197 | AU12: =IF(V12="","",Inputs!I85*AK12-V12) -> 0.0014060151 | AV12: =IF(W12="","",Inputs!J85*AL12-W12) -> 0.0015180641 | AW12: =IF(X12="","",Inputs!K85*AM12-X12) -> 0.0026732856 | BE12: =IF(V12="","",V12+BF12) -> 1.5981825 | BF12: =IF(W12="","",W12+BG12) -> 1.1120414 | BG12: =IF(X12="","",X12) -> 0.64053098
A13: Origin 5 | B13: =Inputs!L9 -> 14525373 | C13: =B13/$B$9 -> 0.93872219 | D13: =C13+D12 -> 4.7430799 | E13: =Inputs!L62 -> 452.87066 | F13: =SUM(Inputs!G71:G74) -> 1937.3214 | G13: =1+F13+$B$5*D12 -> 1938.3214 | H13: =E13+$B$5*C13 -> 452.87066 | I13: =H13/(G13-1) -> 0.23376124 | J13: =(G13+H13-1)/(G13-1) -> 1.2337612 | K13: =SUM(O13:X13)*Inputs!$B$42 -> 85301.539 | L13: =Inputs!M9+K13 -> 9872217.6 | M13: =L13/B13 -> 0.67965331 | N13: Origin 5 | U13: =Inputs!H85*$I$13 -> 2.3303753 | V13: =Inputs!I85*$I$13*$J$12 -> 0.49180084 | W13: =Inputs!J85*$I$13*$J$11*$J$12 -> 0.47699979 | X13: =Inputs!K85*$I$13*$J$10*$J$11*$J$12 -> 0.64798814 | Z13: =(G13+H13-1)/(G13-1) -> 1.2337612 | AA13: =((G13+H13-1)*(G13+H13-2))/((G13-1)*(G13-2)) -> 1.5223157 | AB13: =SUMPRODUCT(O13:X13,1+AD13:AM13)+SUMPRODUCT(AN13:AW13,2*AX13:BG13-O13:X13) -> 5.479834 | AC13: =AB13*Inputs!$B$42^2 -> 2.5592385e+09 | AJ13: =($H$13+1)/($G$13-2) -> 0.23439841 | AK13: =AJ13*($AA$12/$Z$12) -> 0.30488462 | AL13: =AK13*($AA$11/$Z$11) -> 0.45406844 | AM13: =AL13*($AA$10/$Z$10) -> 0.88923526 | AT13: =IF(U13="","",Inputs!H85*AJ13-U13) -> 0.0063519496 | AU13: =IF(V13="","",Inputs!I85*AK13-V13) -> 0.0014166647 | AV13: =IF(W13="","",Inputs!J85*AL13-W13) -> 0.0015301886 | AW13: =IF(X13="","",Inputs!K85*AM13-X13) -> 0.002696863 | BD13: =IF(U13="","",U13+BE13) -> 3.9471641 | BE13: =IF(V13="","",V13+BF13) -> 1.6167888 | BF13: =IF(W13="","",W13+BG13) -> 1.1249879 | BG13: =IF(X13="","",X13) -> 0.64798814
A14: Origin 6 | B14: =Inputs!L10 -> 15025923 | C14: =B14/$B$9 -> 0.97107098 | D14: =C14+D13 -> 5.7141509 | E14: =Inputs!L63 -> 459.7578 | F14: =SUM(Inputs!F71:F75) -> 2373.6385 | G14: =1+F14+$B$5*D13 -> 2374.6385 | H14: =E14+$B$5*C14 -> 459.7578 | I14: =H14/(G14-1) -> 0.19369327 | J14: =(G14+H14-1)/(G14-1) -> 1.1936933 | K14: =SUM(O14:X14)*Inputs!$B$42 -> 156493.89 | L14: =Inputs!M10+K14 -> 10092247 | M14: =L14/B14 -> 0.67165568 | N14: Origin 6 | T14: =Inputs!G85*$I$14 -> 3.2063154 | U14: =Inputs!H85*$I$14*$J$13 -> 2.3823141 | V14: =Inputs!I85*$I$14*$J$12*$J$13 -> 0.50276196 | W14: =Inputs!J85*$I$14*$J$11*$J$12*$J$13 -> 0.48763103 | X14: =Inputs!K85*$I$14*$J$10*$J$11*$J$12*$J$13 -> 0.66243033 | Z14: =(G14+H14-1)/(G14-1) -> 1.1936933 | AA14: =((G14+H14-1)*(G14+H14-2))/((G14-1)*(G14-2)) -> 1.4250011 | AB14: =SUMPRODUCT(O14:X14,1+AD14:AM14)+SUMPRODUCT(AN14:AW14,2*AX14:BG14-O14:X14) -> 9.5592344 | AC14: =AB14*Inputs!$B$42^2 -> 4.4644347e+09 | AI14: =($H$14+1)/($G$14-2) -> 0.19419637 | AJ14: =AI14*($AA$13/$Z$13) -> 0.2396154 | AK14: =AJ14*($AA$12/$Z$12) -> 0.31167042 | AL14: =AK14*($AA$11/$Z$11) -> 0.46417463 | AM14: =AL14*($AA$10/$Z$10) -> 0.90902694 | AS14: =IF(T14="","",Inputs!G85*AI14-T14) -> 0.0083282334 | AT14: =IF(U14="","",Inputs!H85*AJ14-U14) -> 0.0064216505 | AU14: =IF(V14="","",Inputs!I85*AK14-V14) -> 0.0014330693 | AV14: =IF(W14="","",Inputs!J85*AL14-W14) -> 0.0015495751 | AW14: =IF(X14="","",Inputs!K85*AM14-X14) -> 0.0027369572 | BC14: =IF(T14="","",T14+BD14) -> 7.2414529 | BD14: =IF(U14="","",U14+BE14) -> 4.0351374 | BE14: =IF(V14="","",V14+BF14) -> 1.6528233 | BF14: =IF(W14="","",W14+BG14) -> 1.1500614 | BG14: =IF(X14="","",X14) -> 0.66243033
A15: Origin 7 | B15: =Inputs!L11 -> 14832965 | C15: =B15/$B$9 -> 0.95860079 | D15: =C15+D14 -> 6.6727517 | E15: =Inputs!L64 -> 429.50767 | F15: =SUM(Inputs!E71:E76) -> 2791.961 | G15: =1+F15+$B$5*D14 -> 2792.961 | H15: =E15+$B$5*C15 -> 429.50767 | I15: =H15/(G15-1) -> 0.15383727 | J15: =(G15+H15-1)/(G15-1) -> 1.1538373 | K15: =SUM(O15:X15)*Inputs!$B$42 -> 286120.73 | L15: =Inputs!M11+K15 -> 9568142.9 | M15: =L15/B15 -> 0.64505935 | N15: Origin 7 | S15: =Inputs!F85*$I$15 -> 6.3742901 | T15: =Inputs!G85*$I$15*$J$14 -> 3.0398072 | U15: =Inputs!H85*$I$15*$J$13*$J$14 -> 2.2585973 | V15: =Inputs!I85*$I$15*$J$12*$J$13*$J$14 -> 0.47665286 | W15: =Inputs!J85*$I$15*$J$11*$J$12*$J$13*$J$14 -> 0.46230769 | X15: =Inputs!K85*$I$15*$J$10*$J$11*$J$12*$J$13*$J$14 -> 0.62802943 | Z15: =(G15+H15-1)/(G15-1) -> 1.1538373 | AA15: =((G15+H15-1)*(G15+H15-2))/((G15-1)*(G15-2)) -> 1.331404 | AB15: =SUMPRODUCT(O15:X15,1+AD15:AM15)+SUMPRODUCT(AN15:AW15,2*AX15:BG15-O15:X15) -> 16.658408 | AC15: =AB15*Inputs!$B$42^2 -> 7.7799511e+09 | AH15: =($H$15+1)/($G$15-2) -> 0.15425069 | AI15: =AH15*($AA$14/$Z$14) -> 0.1841406 | AJ15: =AI15*($AA$13/$Z$13) -> 0.22720777 | AK15: =AJ15*($AA$12/$Z$12) -> 0.29553168 | AL15: =AK15*($AA$11/$Z$11) -> 0.44013899 | AM15: =AL15*($AA$10/$Z$10) -> 0.8619562 | AR15: =IF(S15="","",Inputs!F85*AH15-S15) -> 0.017130145 | AS15: =IF(T15="","",Inputs!G85*AI15-T15) -> 0.0083775696 | AT15: =IF(U15="","",Inputs!H85*AJ15-U15) -> 0.0064462054 | AU15: =IF(V15="","",Inputs!I85*AK15-V15) -> 0.0014342202 | AV15: =IF(W15="","",Inputs!J85*AL15-W15) -> 0.0015424252 | AW15: =IF(X15="","",Inputs!K85*AM15-X15) -> 0.0026945231 | BB15: =IF(S15="","",S15+BC15) -> 13.239685 | BC15: =IF(T15="","",T15+BD15) -> 6.8653945 | BD15: =IF(U15="","",U15+BE15) -> 3.8255873 | BE15: =IF(V15="","",V15+BF15) -> 1.56699 | BF15: =IF(W15="","",W15+BG15) -> 1.0903371 | BG15: =IF(X15="","",X15) -> 0.62802943
